Workbook

Sheet オファーリスト
C1: 更新日：2025/12/24 | F1: SJOSP記載欄
C2: 起案者 | F2: 商品コードのセルの色 | M2: SECRET：C
C3: SJOSP | G3: 新規取得 | M3: 作成者 | N3: 起案者と同一
G4: 構成変更 | M4: 作成日 | N4: =D5 -> 0 | O4: ←D５セルより計算式で引っ張ってます
C5: 作成日 | G5: 既存流用 | M5: 廃棄日 | N5: 作成日より一年
C6: 起案者Section名
C7: 起案者名 | F7: オファー表現 メディア限定の有無
C8: 放映・出稿・アップ 開始予定日 | F8: 限定セット
A9: 要 | C9: コード取得完了予定日 | E9: 依頼から、基本3週間目目取得完了 | F9: 限定価格
C10: コード精査担当者 | F10: ※FY22法務オファー新ルールにより、メディア限定表現をしているかどうか
E11: ※すべて税込み価格で記載
C12: チャネル名 | D12: オファー詳細 | G12: WEB：施策名 | H12: プリント：素材コード | K12: TV：素材コード | N12: アプグレードあり/なし
B15: 【メイン販売オファー：主商品（1枚セットなど）】
C16: ★入力 | F16: ★入力 | G16: 自動反映 | H16: ★入力 | I16: 自動反映 | J16: 自動反映 | K16: 自動反映 | L16: 自動反映 | M16: 自動反映 | N16: ★入力 | O16: 自動反映 | P16: ★入力 | Q16: 自動反映 | R16: 自動反映 | S16: 自動反映 | T16: 自動反映 | U16: 自動反映 | V16: 自動反映 | W16: 自動反映 | X16: ★入力 | Y16: プルダウン | Z16: プルダウン | AA16: プルダウン | AB16: プルダウン | AC16: プルダウン | AD16: プルダウン | AE16: プルダウン | AF16: プルダウン | AG16: プルダウン | AH16: ★入力 | AI16: プルダウン | AJ16: ★入力 | AK16: ★入力 | AL16: ★入力 | AM16: ★入力 | AN16: プルダウン | AO16: プルダウン | AP16: ★入力 | AQ16: ★入力 | AR16: プルダウン | AS16: ★入力 | AT16: プルダウン | AU16: ★入力 | AV16: ★入力 | AW16: ★入力
I17: 単品価格 | K17: 単品合計価格 | M17: 販売価格 | O17: VU価格 | Q17: 割引内容 単品合計価格⇒販売価格 | T17: 割引内容 販売価格⇒VU価格 | W17: 送料 | Y17: 返品関連 | AA17: その他 | AF17: 定期商品 | AN17: キャッシュバック | AT17: 超分割 ※9,000円以下(送料込み・税込み)は不可 ※送料込みの価格
A18: ｺｰﾄﾞ数 | B18: 文字数 | C18: 商品グループ | D18: 商品コード ※8文字まで | E18: 商品名（カタカナ・数値は半角のみ可） ※40文字まで（全角は2文字、半角は1文字） | F18: SKU | G18: SKU名 | H18: 数量 | I18: 税抜 | J18: 税込 | K18: 税抜 | L18: 税込 | M18: 税抜 | N18: 税込 | O18: 税抜 | P18: 税込 | Q18: 割引率 | R18: 割引額 （税抜） | S18: 割引額 (税込） | T18: 割引率 | U18: 割引額 （税抜） | V18: 割引額 (税込） | W18: 税抜 | X18: 税込 | Y18: 返品不可区分 | Z18: 返品期間 | AA18: 消費税区分 | AB18: 翌日配送 フラグ | AC18: 【AT/OM補正】 | AD18: 【クレジット分割払】 | AE18: 【ゆうパケ フラグ】 | AF18: 有/無 | AG18: 定期商品種別 | AH18: 定期T2注文品番 | AI18: デフォルトお届け間隔 | AJ18: デフォルトお届け間隔数 | AK18: 初期の間隔 | AL18: 継続商品の注文品番 | AM18: 継続商品の販売価格（税抜） | AN18: キャッシュバック情報登録 | AO18: キャッシュバック対象フラグ | AP18: キャッシュバック 受付期間 | AQ18: キャッシュバック 金額 | AR18: キャッシュバック 単位 | AS18: キャッシュバック 条件 | AT18: ショッピング クレジット (WEBのみ) | AU18: 支払回数 (WEBのみ) | AV18: 初月 (WEBのみ) | AW18: 次月以降 (WEBのみ)
A19: =LENB(D19) -> 0 | B19: =LENB(E19) -> 0 | K19: =SUM(K20:K27) -> 0 | L19: =SUM(L20:L27) -> 0 | M19: =ROUNDUP(N19/1.1,0) -> 0 | O19: =ROUNDUP(P19/1.1,0) -> 0 | Q19: =1-(N19/L19) -> #DIV/0! | R19: =K19-M19 -> 0 | S19: =L19-N19 -> 0 | T19: =1-(P19/N19) -> #DIV/0! | U19: =M19-O19 -> 0 | V19: =N19-P19 -> 0 | W19: =ROUNDUP(X19/1.1,0) -> 0
G20: =IFERROR(VLOOKUP(F20,[4]EX0054_在庫表!$A:$B,2,FALSE),"") | I20: =IFERROR(VLOOKUP(F20,[5]入力シート!$C:$AH,18,FALSE),0) | J20: =ROUNDDOWN(I20*1.1,0) -> 0 | K20: =IFERROR((I20*H20),"") -> 0 | L20: =IFERROR((J20*H20),"") -> 0
G21: =IFERROR(VLOOKUP(F21,[4]EX0054_在庫表!$A:$B,2,FALSE),"") | I21: =IFERROR(VLOOKUP(F21,[5]入力シート!$C:$AH,18,FALSE),0) | J21: =ROUNDDOWN(I21*1.1,0) -> 0 | K21: =IFERROR((I21*H21),"") -> 0 | L21: =IFERROR((J21*H21),"") -> 0
G22: =IFERROR(VLOOKUP(F22,[4]EX0054_在庫表!$A:$B,2,FALSE),"") | I22: =IFERROR(VLOOKUP(F22,[5]入力シート!$C:$AH,18,FALSE),0) | J22: =ROUNDDOWN(I22*1.1,0) -> 0 | K22: =IFERROR((I22*H22),"") -> 0 | L22: =IFERROR((J22*H22),"") -> 0
G23: =IFERROR(VLOOKUP(F23,[4]EX0054_在庫表!$A:$B,2,FALSE),"") | I23: =IFERROR(VLOOKUP(F23,[5]入力シート!$C:$AH,18,FALSE),0) | J23: =ROUNDDOWN(I23*1.1,0) -> 0 | K23: =IFERROR((I23*H23),"") -> 0 | L23: =IFERROR((J23*H23),"") -> 0
G24: =IFERROR(VLOOKUP(F24,[4]EX0054_在庫表!$A:$B,2,FALSE),"") | I24: =IFERROR(VLOOKUP(F24,[5]入力シート!$C:$AH,18,FALSE),0) | J24: =ROUNDDOWN(I24*1.1,0) -> 0 | K24: =IFERROR((I24*H24),"") -> 0 | L24: =IFERROR((J24*H24),"") -> 0
G25: =IFERROR(VLOOKUP(F25,[4]EX0054_在庫表!$A:$B,2,FALSE),"") | I25: =IFERROR(VLOOKUP(F25,[5]入力シート!$C:$AH,18,FALSE),0) | J25: =ROUNDDOWN(I25*1.1,0) -> 0 | K25: =IFERROR((I25*H25),"") -> 0 | L25: =IFERROR((J25*H25),"") -> 0
G26: =IFERROR(VLOOKUP(F26,[4]EX0054_在庫表!$A:$B,2,FALSE),"") | I26: =IFERROR(VLOOKUP(F26,[5]入力シート!$C:$AH,18,FALSE),0) | J26: =ROUNDDOWN(I26*1.1,0) -> 0 | K26: =IFERROR((I26*H26),"") -> 0 | L26: =IFERROR((J26*H26),"") -> 0
G27: =IFERROR(VLOOKUP(F27,[4]EX0054_在庫表!$A:$B,2,FALSE),"") | I27: =IFERROR(VLOOKUP(F27,[5]入力シート!$C:$AH,18,FALSE),0) | J27: =ROUNDDOWN(I27*1.1,0) -> 0 | K27: =IFERROR((I27*H27),"") -> 0 | L27: =IFERROR((J27*H27),"") -> 0
A28: =LENB(D28) -> 0 | B28: =LENB(E28) -> 0 | K28: =SUM(K29:K36) -> 0 | L28: =SUM(L29:L36) -> 0 | M28: =ROUNDUP(N28/1.1,0) -> 0 | O28: =ROUNDUP(P28/1.1,0) -> 0 | Q28: =1-(N28/L28) -> #DIV/0! | R28: =K28-M28 -> 0 | S28: =L28-N28 -> 0 | T28: =1-(P28/N28) -> #DIV/0! | U28: =M28-O28 -> 0 | V28: =N28-P28 -> 0 | W28: =ROUNDUP(X28/1.1,0) -> 0
I29: 0 | J29: =ROUNDDOWN(I29*1.1,0) -> 0 | K29: =IFERROR((I29*H29),"") -> 0 | L29: =IFERROR((J29*H29),"") -> 0
I30: 0 | J30: =ROUNDDOWN(I30*1.1,0) -> 0 | K30: =IFERROR((I30*H30),"") -> 0 | L30: =IFERROR((J30*H30),"") -> 0
I31: 0 | J31: =ROUNDDOWN(I31*1.1,0) -> 0 | K31: =IFERROR((I31*H31),"") -> 0 | L31: =IFERROR((J31*H31),"") -> 0
I32: 0 | J32: =ROUNDDOWN(I32*1.1,0) -> 0 | K32: =IFERROR((I32*H32),"") -> 0 | L32: =IFERROR((J32*H32),"") -> 0
I33: 0 | J33: =ROUNDDOWN(I33*1.1,0) -> 0 | K33: =IFERROR((I33*H33),"") -> 0 | L33: =IFERROR((J33*H33),"") -> 0
I34: 0 | J34: =ROUNDDOWN(I34*1.1,0) -> 0 | K34: =IFERROR((I34*H34),"") -> 0 | L34: =IFERROR((J34*H34),"") -> 0
I35: 0 | J35: =ROUNDDOWN(I35*1.1,0) -> 0 | K35: =IFERROR((I35*H35),"") -> 0 | L35: =IFERROR((J35*H35),"") -> 0
I36: 0 | J36: =ROUNDDOWN(I36*1.1,0) -> 0 | K36: =IFERROR((I36*H36),"") -> 0 | L36: =IFERROR((J36*H36),"") -> 0
A37: =LENB(D37) -> 0 | B37: =LENB(E37) -> 0 | K37: =SUM(K38:K45) -> 0 | L37: =SUM(L38:L45) -> 0 | M37: =ROUNDUP(N37/1.1,0) -> 0 | O37: =ROUNDUP(P37/1.1,0) -> 0 | Q37: =1-(N37/L37) -> #DIV/0! | R37: =K37-M37 -> 0 | S37: =L37-N37 -> 0 | T37: =1-(P37/N37) -> #DIV/0! | U37: =M37-O37 -> 0 | V37: =N37-P37 -> 0 | W37: =ROUNDUP(X37/1.1,0) -> 0
I38: 0 | J38: =ROUNDDOWN(I38*1.1,0) -> 0 | K38: =IFERROR((I38*H38),"") -> 0 | L38: =IFERROR((J38*H38),"") -> 0
I39: 0 | J39: =ROUNDDOWN(I39*1.1,0) -> 0 | K39: =IFERROR((I39*H39),"") -> 0 | L39: =IFERROR((J39*H39),"") -> 0
I40: 0 | J40: =ROUNDDOWN(I40*1.1,0) -> 0 | K40: =IFERROR((I40*H40),"") -> 0 | L40: =IFERROR((J40*H40),"") -> 0
I41: 0 | J41: =ROUNDDOWN(I41*1.1,0) -> 0 | K41: =IFERROR((I41*H41),"") -> 0 | L41: =IFERROR((J41*H41),"") -> 0
I42: 0 | J42: =ROUNDDOWN(I42*1.1,0) -> 0 | K42: =IFERROR((I42*H42),"") -> 0 | L42: =IFERROR((J42*H42),"") -> 0
...

Sheet VU_FMT
B1: 施策名：【商品G】●●キャンペーン
B2: ＜対応パターン＞ | E2: ＜KUROSHIO MD用のスコアルール＞
B3: ・新規取得 | E3: ・スコア・・・オファーしたい順に１から数を増やす
B4: ・B行追加 | E4: ※SP用：紐づけ済みのVU商品を外す場合は、有効終了日時を過去にする
B5: ・E行追加 | E5: ＜VU表示＞
B6: ・割引率変更 | E6: ・スマホのVUは最大8個までしか表示されない。
B7: ※変更の場合は、変更点が分かるようにセルを黄色にし、変更内容をメモしてください。 | E7: ・PCの場合は2ページ、3ページと8個以上の表示可能。
B8: ※SP用：順番＆スクリプト変更は、デザイナーが行う＝SJOSPには依頼が来ない。
G11: MOG | H11: MOG
G12: toTCI
B13: ★入力 | C13: ★入力 | D13: プルダウン | E13: ★入力 | F13: ★入力 | G13: ★入力 | H13: ★入力 | I13: ★入力 | J13: ★入力 | K13: ★入力 | L13: ★入力 | M13: デザインチームが、TCIに依頼する原稿
B14: ベース商品 商品コード | C14: ベース商品 商品名 | D14: バリューアップ種類選択 | E14: バリューアップセル 商品コード | F14: バリューアップセル 商品名 | G14: 購入前 | H14: 購入後 | I14: 通常価格 (税込) | J14: 割引後価格 （税込） | K14: 割引率（額） | L14: スコア | M14: サイトスクリプト

Sheet アップグレード
A1: UPG情報まとめ
A2: ベース商品コード | C2: UPG商品コード
A3: 商品コード | B3: 商品コード名 | C3: 商品コード | D3: 商品コード名

Sheet 関連リンク
A1: ■SKUごとの単品価格
A2: \\svdw03jpawscv\Data\SKU\SKU情報追加入力.xlsx
A14: ■承認者フロー
A15: \\filesrv\Projects\1402_0005_SJ共有\Channel Promotion【C】\06_Merchandising meeting\コンカー承認者一覧\20230313_Concur承認者一覧.xlsx

Sheet 変更履歴
A1: ■20231116改定
A2: NO | B2: 内容 | C2: 備考
A3: 1 | B3: 「記入例」タブ削除 | C3: 皆様慣れてきたと思うので、フォーマットからは削除します
A4: 2 | B4: 「単品価格・サイズ・カラバリ情報」タブ削除 | C4: 取得コード情報はすべて「オファーリスト」タブに記載ください
A5: 3 | B5: 「関連商品（バリューアップ）」タブ削除 | C5: 取得コード情報はすべて「オファーリスト」タブで管理・VU価格もこちらに記入するため
